Workbook

Sheet COMPARADOR
A1: 📱 Comparativa de Celulares
B3: Selecciona los celulares a comparar
B5: Celular 1 | C5: Celular 2 | D5: Celular 3
B6: SAMSUNG GXY A17 128GB | C6: MOTOROLA G05 128GB | D6: SAMSUNG GXY A06 128GB
A8: Comparativa Detallada
A9: Especificación | B9: =B6 -> SAMSUNG GXY A17 128GB | C9: =C6 -> MOTOROLA G05 128GB | D9: =D6 -> SAMSUNG GXY A06 128GB
A10: Plan | B10: 69.9 | C10: 69.9 | D10: 29.9
A11: Contado | B11: {=IFERROR( INDEX(Caracteristicas!$A:$AAB, _xludf.XMATCH($B$9,Caracteristicas!$A:$A,0), _xludf.XMATCH($A11,Caracteristicas!$1:$1,0) ), "")} | C11: {=IFERROR( INDEX(Caracteristicas!$A:$AAB, _xludf.XMATCH($C$9,Caracteristicas!$A:$A,0), _xludf.XMATCH($A11,Caracteristicas!$1:$1,0) ), "")} | D11: {=IFERROR( INDEX(Caracteristicas!$A:$AAB, _xludf.XMATCH($D$9,Caracteristicas!$A:$A,0), _xludf.XMATCH($A11,Caracteristicas!$1:$1,0) ), "")}
A12: Cuota x 12 meses | B12: {=IFERROR( INDEX(Caracteristicas!$A:$AAB, _xludf.XMATCH($B$9,Caracteristicas!$A:$A,0), _xludf.XMATCH($A12,Caracteristicas!$1:$1,0) ), "")} | C12: {=IFERROR( INDEX(Caracteristicas!$A:$AAB, _xludf.XMATCH($C$9,Caracteristicas!$A:$A,0), _xludf.XMATCH($A12,Caracteristicas!$1:$1,0) ), "")} | D12: {=IFERROR( INDEX(Caracteristicas!$A:$AAB, _xludf.XMATCH($D$9,Caracteristicas!$A:$A,0), _xludf.XMATCH($A12,Caracteristicas!$1:$1,0) ), "")}
A13: Pantalla | B13: {=IFERROR( INDEX(Caracteristicas!$A:$AAB, _xludf.XMATCH($B$9,Caracteristicas!$A:$A,0), _xludf.XMATCH($A13,Caracteristicas!$1:$1,0) ), "")} | C13: {=IFERROR( INDEX(Caracteristicas!$A:$AAB, _xludf.XMATCH($C$9,Caracteristicas!$A:$A,0), _xludf.XMATCH($A13,Caracteristicas!$1:$1,0) ), "")} | D13: {=IFERROR( INDEX(Caracteristicas!$A:$AAB, _xludf.XMATCH($D$9,Caracteristicas!$A:$A,0), _xludf.XMATCH($A13,Caracteristicas!$1:$1,0) ), "")}
A14: Peso | B14: {=IFERROR( INDEX(Caracteristicas!$A:$AAB, _xludf.XMATCH($B$9,Caracteristicas!$A:$A,0), _xludf.XMATCH($A14,Caracteristicas!$1:$1,0) ), "")} | C14: {=IFERROR( INDEX(Caracteristicas!$A:$AAB, _xludf.XMATCH($C$9,Caracteristicas!$A:$A,0), _xludf.XMATCH($A14,Caracteristicas!$1:$1,0) ), "")} | D14: {=IFERROR( INDEX(Caracteristicas!$A:$AAB, _xludf.XMATCH($D$9,Caracteristicas!$A:$A,0), _xludf.XMATCH($A14,Caracteristicas!$1:$1,0) ), "")}
A15: Resistencia | B15: {=IFERROR( INDEX(Caracteristicas!$A:$AAB, _xludf.XMATCH($B$9,Caracteristicas!$A:$A,0), _xludf.XMATCH($A15,Caracteristicas!$1:$1,0) ), "")} | C15: {=IFERROR( INDEX(Caracteristicas!$A:$AAB, _xludf.XMATCH($C$9,Caracteristicas!$A:$A,0), _xludf.XMATCH($A15,Caracteristicas!$1:$1,0) ), "")} | D15: {=IFERROR( INDEX(Caracteristicas!$A:$AAB, _xludf.XMATCH($D$9,Caracteristicas!$A:$A,0), _xludf.XMATCH($A15,Caracteristicas!$1:$1,0) ), "")}
A16: Tasa de Refresco | B16: {=IFERROR( INDEX(Caracteristicas!$A:$AAB, _xludf.XMATCH($B$9,Caracteristicas!$A:$A,0), _xludf.XMATCH($A16,Caracteristicas!$1:$1,0) ), "")} | C16: {=IFERROR( INDEX(Caracteristicas!$A:$AAB, _xludf.XMATCH($C$9,Caracteristicas!$A:$A,0), _xludf.XMATCH($A16,Caracteristicas!$1:$1,0) ), "")} | D16: {=IFERROR( INDEX(Caracteristicas!$A:$AAB, _xludf.XMATCH($D$9,Caracteristicas!$A:$A,0), _xludf.XMATCH($A16,Caracteristicas!$1:$1,0) ), "")}
A17: Procesador | B17: {=IFERROR( INDEX(Caracteristicas!$A:$AAB, _xludf.XMATCH($B$9,Caracteristicas!$A:$A,0), _xludf.XMATCH($A17,Caracteristicas!$1:$1,0) ), "")} | C17: {=IFERROR( INDEX(Caracteristicas!$A:$AAB, _xludf.XMATCH($C$9,Caracteristicas!$A:$A,0), _xludf.XMATCH($A17,Caracteristicas!$1:$1,0) ), "")} | D17: {=IFERROR( INDEX(Caracteristicas!$A:$AAB, _xludf.XMATCH($D$9,Caracteristicas!$A:$A,0), _xludf.XMATCH($A17,Caracteristicas!$1:$1,0) ), "")}
A18: Antutu | B18: {=IFERROR( INDEX(Caracteristicas!$A:$AAB, _xludf.XMATCH($B$9,Caracteristicas!$A:$A,0), _xludf.XMATCH($A18,Caracteristicas!$1:$1,0) ), "")} | C18: {=IFERROR( INDEX(Caracteristicas!$A:$AAB, _xludf.XMATCH($C$9,Caracteristicas!$A:$A,0), _xludf.XMATCH($A18,Caracteristicas!$1:$1,0) ), "")} | D18: {=IFERROR( INDEX(Caracteristicas!$A:$AAB, _xludf.XMATCH($D$9,Caracteristicas!$A:$A,0), _xludf.XMATCH($A18,Caracteristicas!$1:$1,0) ), "")}
A19: RAM | B19: {=IFERROR( INDEX(Caracteristicas!$A:$AAB, _xludf.XMATCH($B$9,Caracteristicas!$A:$A,0), _xludf.XMATCH($A19,Caracteristicas!$1:$1,0) ), "")} | C19: {=IFERROR( INDEX(Caracteristicas!$A:$AAB, _xludf.XMATCH($C$9,Caracteristicas!$A:$A,0), _xludf.XMATCH($A19,Caracteristicas!$1:$1,0) ), "")} | D19: {=IFERROR( INDEX(Caracteristicas!$A:$AAB, _xludf.XMATCH($D$9,Caracteristicas!$A:$A,0), _xludf.XMATCH($A19,Caracteristicas!$1:$1,0) ), "")}
A20: Almacenamiento | B20: {=IFERROR( INDEX(Caracteristicas!$A:$AAB, _xludf.XMATCH($B$9,Caracteristicas!$A:$A,0), _xludf.XMATCH($A20,Caracteristicas!$1:$1,0) ), "")} | C20: {=IFERROR( INDEX(Caracteristicas!$A:$AAB, _xludf.XMATCH($C$9,Caracteristicas!$A:$A,0), _xludf.XMATCH($A20,Caracteristicas!$1:$1,0) ), "")} | D20: {=IFERROR( INDEX(Caracteristicas!$A:$AAB, _xludf.XMATCH($D$9,Caracteristicas!$A:$A,0), _xludf.XMATCH($A20,Caracteristicas!$1:$1,0) ), "")}
A21: Cámaras | B21: {=IFERROR( INDEX(Caracteristicas!$A:$AAB, _xludf.XMATCH($B$9,Caracteristicas!$A:$A,0), _xludf.XMATCH($A21,Caracteristicas!$1:$1,0) ), "")} | C21: {=IFERROR( INDEX(Caracteristicas!$A:$AAB, _xludf.XMATCH($C$9,Caracteristicas!$A:$A,0), _xludf.XMATCH($A21,Caracteristicas!$1:$1,0) ), "")} | D21: {=IFERROR( INDEX(Caracteristicas!$A:$AAB, _xludf.XMATCH($D$9,Caracteristicas!$A:$A,0), _xludf.XMATCH($A21,Caracteristicas!$1:$1,0) ), "")}
A22: Estabilización Óptica | B22: {=IFERROR( INDEX(Caracteristicas!$A:$AAB, _xludf.XMATCH($B$9,Caracteristicas!$A:$A,0), _xludf.XMATCH($A22,Caracteristicas!$1:$1,0) ), "")} | C22: {=IFERROR( INDEX(Caracteristicas!$A:$AAB, _xludf.XMATCH($C$9,Caracteristicas!$A:$A,0), _xludf.XMATCH($A22,Caracteristicas!$1:$1,0) ), "")} | D22: {=IFERROR( INDEX(Caracteristicas!$A:$AAB, _xludf.XMATCH($D$9,Caracteristicas!$A:$A,0), _xludf.XMATCH($A22,Caracteristicas!$1:$1,0) ), "")}
... A29: Huella | B29: {=IFERROR( INDEX(Caracteristicas!$A:$AAB, _xludf.XMATCH($B$9,Caracteristicas!$A:$A,0), _xludf.XMATCH($A29,Caracteristicas!$1:$1,0) ), "")} | C29: {=IFERROR( INDEX(Caracteristicas!$A:$AAB, _xludf.XMATCH($C$9,Caracteristicas!$A:$A,0), _xludf.XMATCH($A29,Caracteristicas!$1:$1,0) ), "")} | D29: {=IFERROR( INDEX(Caracteristicas!$A:$AAB, _xludf.XMATCH($D$9,Caracteristicas!$A:$A,0), _xludf.XMATCH($A29,Caracteristicas!$1:$1,0) ), "")}

Sheet Caracteristicas
A1: EQUIPO | B1: CONTADO | C1: Cuota x 12 meses | D1: Pantalla | E1: Peso | F1: Resistencia | G1: Tasa de Refresco | H1: Procesador | I1: Antutu | J1: RAM | K1: Almacenamiento | L1: Ampliable | M1: Cámaras | N1: Estabilización Óptica | O1: Grabación de Video | P1: Cámara Frontal | Q1: Batería | R1: Carga Rápida | S1: Carga Inalámbrica | T1: Bluetooth | U1: NFC | V1: Huella | W1: Actualización | AF1: PLANES
A2: HONOR X5B | B2: {=IFERROR( _xludf.XLOOKUP("*"&SUBSTITUTE(TRIM(A2)," ","*")&"*", 'RENO CONT'!$C:$C, 'RENO CONT'!$D:$D, "", 2), "")} | C2: {=IFERROR( _xludf.XLOOKUP("*"&SUBSTITUTE(TRIM(A2)," ","*")&"*", 'RENO FINAN'!$A:$A, 'RENO FINAN'!$C:$C, "", 2), "")} | D2: 6.56", HD+, TFT LCD (IPS) | E2: 194 g | F2: - | G2: 90 Hz | H2: Helio G36 (12 nm) | I2: 127K | J2: 4 GB (física) + hasta 4 GB (RAM Boost) | K2: 128 GB | L2: Hasta 1Tb | M2: 13 Mpx (ƒ/ 1.8) + 0.3 Mpx | N2: NO | O2: 1080p@30fps | P2: 5 Mpx | Q2: 5200 mAh | R2: 10.0W | S2: NO | T2: 5.1 | U2: NO | V2: lateral | W2: ~2 años | AF2: 29.9
A3: HONOR X5C | B3: {=IFERROR( _xludf.XLOOKUP("*"&SUBSTITUTE(TRIM(A3)," ","*")&"*", 'RENO CONT'!$C:$C, 'RENO CONT'!$D:$D, "", 2), "")} | C3: {=IFERROR( _xludf.XLOOKUP("*"&SUBSTITUTE(TRIM(A3)," ","*")&"*", 'RENO FINAN'!$A:$A, 'RENO FINAN'!$C:$C, "", 2), "")} | D3: 6.74", HD+, TFT LCD (IPS) | E3: 186 g | F3: - | G3: 90 Hz | H3: Helio G81 (12 nm) | I3: 280K | J3: 4 GB (física) + hasta 4 GB (RAM Boost) | K3: 128 GB | L3: Hasta 1Tb | M3: 50 Mpx (ƒ/ 2.2) + 0.8 Mpx (QVGA) | N3: NO | O3: 1080p@30fps | P3: 5 Mpx | Q3: 5260 mAh | R3: 15.0W | S3: NO | T3: 5.1 | U3: NO | V3: lateral | W3: -
A4: HONOR X6C | B4: {=IFERROR( _xludf.XLOOKUP("*"&SUBSTITUTE(TRIM(A4)," ","*")&"*", 'RENO CONT'!$C:$C, 'RENO CONT'!$D:$D, "", 2), "")} | C4: {=IFERROR( _xludf.XLOOKUP("*"&SUBSTITUTE(TRIM(A4)," ","*")&"*", 'RENO FINAN'!$A:$A, 'RENO FINAN'!$C:$C, "", 2), "")} | D4: 6.56", HD+, TFT LCD (IPS) | E4: 199 g | F4: IP64 | G4: 120Hz | H4: Helio G81 Ultra (12 nm) | I4: 287K | J4: 6 GB (física) + hasta 6 GB (RAM Boost) | K4: 256 GB | L4: Hasta 1Tb | M4: 50 Mpx (ƒ/ 1.8) + 2 Mpx Retrato (ƒ/ 2.4) | N4: NO | O4: 1080p@30fps | P4: 5 Mpx | Q4: 5300 mAh | R4: 35.0W | S4: NO | T4: 5.1 | U4: NO | V4: lateral | W4: ~2 años | AF4: 39.9
A5: HONOR X7C | B5: {=IFERROR( _xludf.XLOOKUP("*"&SUBSTITUTE(TRIM(A5)," ","*")&"*", 'RENO CONT'!$C:$C, 'RENO CONT'!$D:$D, "", 2), "")} | C5: {=IFERROR( _xludf.XLOOKUP("*"&SUBSTITUTE(TRIM(A5)," ","*")&"*", 'RENO FINAN'!$A:$A, 'RENO FINAN'!$C:$C, "", 2), "")} | D5: 6.77", HD, LCD IPS | E5: 196 g | F5: IP64 | G5: 120Hz | H5: Snapdragon 685 (6 nm) | I5: 321K | J5: 8 GB (física) + hasta 8 GB (RAM Boost) | K5: 256 GB | L5: - | M5: 108 Mpx (ƒ/ 1.8) + 2 Mpx Retrato (ƒ/ 2.4) | N5: NO | O5: 1080p@30fps | P5: 8 Mpx | Q5: 6000 mAh | R5: 35.0W | S5: NO | T5: 5.1 | U5: NO | V5: lateral | W5: ~2 años | AF5: 49.9
A6: HONOR X7D | B6: {=IFERROR( _xludf.XLOOKUP("*"&SUBSTITUTE(TRIM(A6)," ","*")&"*", 'RENO CONT'!$C:$C, 'RENO CONT'!$D:$D, "", 2), "")} | C6: {=IFERROR( _xludf.XLOOKUP("*"&SUBSTITUTE(TRIM(A6)," ","*")&"*", 'RENO FINAN'!$A:$A, 'RENO FINAN'!$C:$C, "", 2), "")} | D6: 6.77", HD, TFT LCD | E6: 208 g | F6: IP65 | G6: 120Hz | H6: Snapdragon 685 (6 nm) | I6: 350K | J6: 8 GB (física) + hasta 8 GB (RAM Boost) | K6: 256 GB | L6: - | M6: 108 Mpx (ƒ/ 1.8) + 2 Mpx (ƒ/ 2.4) | N6: NO | O6: 1080p@30fps | P6: 8 Mpx | Q6: 6500mAh | R6: 35.0W | S6: NO | T6: 5 | U6: - | V6: lateral | W6: -
A7: HONOR X8C 256GB | B7: {=IFERROR( _xludf.XLOOKUP("*"&SUBSTITUTE(TRIM(A7)," ","*")&"*", 'RENO CONT'!$C:$C, 'RENO CONT'!$D:$D, "", 2), "")} | C7: {=IFERROR( _xludf.XLOOKUP("*"&SUBSTITUTE(TRIM(A7)," ","*")&"*", 'RENO FINAN'!$A:$A, 'RENO FINAN'!$C:$C, "", 2), "")} | D7: 6.77", FHD+, AMOLED | E7: 174 g | F7: IP64 | G7: 120Hz | H7: Snapdragon 685 (6 nm) | I7: 321K | J7: 8 GB (física) + hasta 8 GB (RAM Boost) | K7: 256 GB | L7: - | M7: 108 Mpx (ƒ/ 1.75) + 5 Mpx Retrato (ƒ/ 2.2) | N7: SI | O7: 1080p@30fps | P7: 50 MP | Q7: 5000 mAh | R7: 35.0W | S7: NO | T7: 5 | U7: NO | V7: Pantalla | W7: ~2 años | AF7: 59.9
A8: HONOR MAGIC 7 LITE 512GB | B8: {=IFERROR( _xludf.XLOOKUP("*"&SUBSTITUTE(TRIM(A8)," ","*")&"*", 'RENO CONT'!$C:$C, 'RENO CONT'!$D:$D, "", 2), "")} | C8: {=IFERROR( _xludf.XLOOKUP("*"&SUBSTITUTE(TRIM(A8)," ","*")&"*", 'RENO FINAN'!$A:$A, 'RENO FINAN'!$C:$C, "", 2), "")} | D8: 6.78", QHD, AMOLED | E8: 189 g | F8: IP65 | G8: 120 Hz | H8: Snapdragon 6 Gen1 (4 nm) | I8: 575K | J8: 8 GB (física) + hasta 8 GB (RAM Boost) | K8: 512 GB | L8: - | M8: 108 Mpx (ƒ/ 1.75) + 5 Mpx UGA (ƒ/ 2.2) | N8: SI | O8: 4K | P8: 16 Mpx | Q8: 6600 mAh | R8: 66.0W | S8: NO | T8: 5.1 | U8: - | V8: Pantalla | W8: Hasta Enero 2031 | AF8: 69.9
A9: HONOR MAGIC 8 LITE 512GB 5G | B9: {=IFERROR( _xludf.XLOOKUP("*"&SUBSTITUTE(TRIM(A9)," ","*")&"*", 'RENO CONT'!$C:$C, 'RENO CONT'!$D:$D, "", 2), "")} | C9: {=IFERROR( _xludf.XLOOKUP("*"&SUBSTITUTE(TRIM(A9)," ","*")&"*", 'RENO FINAN'!$A:$A, 'RENO FINAN'!$C:$C, "", 2), "")} | D9: 6.79", QHD, AMOLED | E9: 193 g | F9: IP68, IP69 y IP69K | G9: 120 Hz | H9: Snapdragon 6 Gen 4 (4 nm) | I9: 894K | J9: 8 GB (física) + hasta 8 GB (RAM Boost) | K9: 512 GB | L9: - | M9: 108 Mpx (ƒ/ 1.75) + 5 Mpx UGA (ƒ/ 2.2) | N9: SI | O9: 4K | P9: 16 Mpx | Q9: 8300mAh | R9: 66.0W | S9: NO | T9: 5.2 | U9: NO | V9: Pantalla | W9: -
A10: HONOR 400 LITE | B10: {=IFERROR( _xludf.XLOOKUP("*"&SUBSTITUTE(TRIM(A10)," ","*")&"*", 'RENO CONT'!$C:$C, 'RENO CONT'!$D:$D, "", 2), "")} | C10: {=IFERROR( _xludf.XLOOKUP("*"&SUBSTITUTE(TRIM(A10)," ","*")&"*", 'RENO FINAN'!$A:$A, 'RENO FINAN'!$C:$C, "", 2), "")} | D10: 6.7", FHD, AMOLED | E10: 171 g | F10: IP65 | G10: 120 Hz | H10: Dimensity 7025 (6 nm) | I10: 470k | J10: 8 GB (física) + hasta 8 GB (RAM Boost) | K10: 256 GB | L10: - | M10: 108 Mpx (ƒ/ 1.75) + 5 Mpx UGA (ƒ/ 2.2) | N10: NO | O10: 1080p@30fps | P10: 16 Mpx | Q10: 5230 mAh | R10: 33W | S10: NO | T10: 5.3 | U10: NO | V10: Pantalla | W10: -
A11: HONOR 400 | B11: {=IFERROR( _xludf.XLOOKUP("*"&SUBSTITUTE(TRIM(A11)," ","*")&"*", 'RENO CONT'!$C:$C, 'RENO CONT'!$D:$D, "", 2), "")} | C11: {=IFERROR( _xludf.XLOOKUP("*"&SUBSTITUTE(TRIM(A11)," ","*")&"*", 'RENO FINAN'!$A:$A, 'RENO FINAN'!$C:$C, "", 2), "")} | D11: 6.55", QHD, AMOLED | E11: 184 g | F11: IP66 | G11: 120 Hz | H11: Snapdragon 7 Gen 3 (4 nm) | I11: 845K | J11: 12 GB (física) + hasta 12 GB (RAM Boost) | K11: 512 GB UFS 3.1 | L11: - | M11: 200 Mpx (ƒ/ 1.9) + 12 Mpx UGA + Macro (ƒ/ 2.2) | N11: SI | O11: 4K | P11: 50 Mpx | Q11: 5300 mAh | R11: 66.0W | S11: NO | T11: 5.4 | U11: SI | V11: Pantalla | W11: Hasta Mayo 2031 | AF11: 79.9
A12: IPHONE 13 128GB | B12: {=IFERROR( _xludf.XLOOKUP("*"&SUBSTITUTE(TRIM(A12)," ","*")&"*", 'RENO CONT'!$C:$C, 'RENO CONT'!$D:$D, "", 2), "")} | C12: {=IFERROR( _xludf.XLOOKUP("*"&SUBSTITUTE(TRIM(A12)," ","*")&"*", 'RENO FINAN'!$A:$A, 'RENO FINAN'!$C:$C, "", 2), "")} | D12: 6.1", FHD, Oled | E12: 174 g | F12: IP68 | G12: 60 Hz | H12: A15 Bionic (5 nm) | I12: 1256K | J12: 4 GB | K12: 128 GB NVMe | L12: NO | M12: 12 Mpx (ƒ/ 1.6) + 12 Mpx UGA (ƒ/ 2.4) | N12: SI | O12: 4K | P12: 12 Mpx | Q12: 3240 mAh | R12: 20.0W | S12: SI | T12: 5 | U12: SI | V12: NO | W12: Hasta el 2028 | AF12: 99.9
A13: IPHONE 15 128GB | B13: {=IFERROR( _xludf.XLOOKUP("*"&SUBSTITUTE(TRIM(A13)," ","*")&"*", 'RENO CONT'!$C:$C, 'RENO CONT'!$D:$D, "", 2), "")} | C13: {=IFERROR( _xludf.XLOOKUP("*"&SUBSTITUTE(TRIM(A13)," ","*")&"*", 'RENO FINAN'!$A:$A, 'RENO FINAN'!$C:$C, "", 2), "")} | D13: 6.1", QHD, Oled | E13: 171 g | F13: IP68 | G13: 60 Hz | H13: A16 Bionic (4 nm) | I13: 1470k | J13: 6 GB | K13: 128 GB NVMe | L13: NO | M13: 48 Mpx (ƒ/ 1.6) + 12 Mpx UGA (ƒ/ 2.4) | N13: SI | O13: 4K | P13: 12 Mpx | Q13: 3349 mAh | R13: 18.0W | S13: SI | T13: 5.3 | U13: SI | V13: NO | W13: Hasta el 2029
A14: IPHONE 16 128GB | B14: {=IFERROR( _xludf.XLOOKUP("*"&SUBSTITUTE(TRIM(A14)," ","*")&"*", 'RENO CONT'!$C:$C, 'RENO CONT'!$D:$D, "", 2), "")} | C14: {=IFERROR( _xludf.XLOOKUP("*"&SUBSTITUTE(TRIM(A14)," ","*")&"*", 'RENO FINAN'!$A:$A, 'RENO FINAN'!$C:$C, "", 2), "")} | D14: 6.1", QHD, Oled | E14: 171 g | F14: IP68 | G14: 60 Hz | H14: A18 Bionic (3 nm) | I14: 1586k | J14: 8 GB | K14: 128 GB NVMe | L14: NO | M14: 48 Mpx (ƒ/ 1.6) + 12 Mpx UGA (ƒ/ 2.2) | N14: SI | O14: 4K | P14: 12 Mpx | Q14: 3561 mAh | R14: 18.0W | S14: SI | T14: 5.3 | U14: SI | V14: NO | W14: Hasta el 2030
A15: IPHONE 17 256GB | B15: {=IFERROR( _xludf.XLOOKUP("*"&SUBSTITUTE(TRIM(A15)," ","*")&"*", 'RENO CONT'!$C:$C, 'RENO CONT'!$D:$D, "", 2), "")} | C15: {=IFERROR( _xludf.XLOOKUP("*"&SUBSTITUTE(TRIM(A15)," ","*")&"*", 'RENO FINAN'!$A:$A, 'RENO FINAN'!$C:$C, "", 2), "")} | D15: 6.3", QHD, Oled | E15: 177 g | F15: IP68 | G15: 120 Hz | H15: A19 Bionic (3 nm) | I15: 2084k | J15: 8 GB | K15: 256 GB NVMe | L15: NO | M15: 48 Mpx (ƒ/ 1.6) + 12 Mpx UGA (ƒ/ 2.2) | N15: SI | O15: 4k | P15: 18 Mpx | Q15: 3600 mAh | R15: 18.0W | S15: SI | T15: 6 | U15: SI | V15: NO | W15: Hasta el 2031
A16: IPHONE 17 PRO MAX 512GB | B16: {=IFERROR( _xludf.XLOOKUP("*"&SUBSTITUTE(TRIM(A16)," ","*")&"*", 'RENO CONT'!$C:$C, 'RENO CONT'!$D:$D, "", 2), "")} | C16: {=IFERROR( _xludf.XLOOKUP("*"&SUBSTITUTE(TRIM(A16)," ","*")&"*", 'RENO FINAN'!$A:$A, 'RENO FINAN'!$C:$C, "", 2), "")} | D16: 6.9", QHD, Oled | E16: 233 g | F16: IP68 | G16: 120 Hz | H16: A19 Pro (3 nm) | I16: 2309k | J16: 12 GB | K16: 512 GB NVMe | L16: NO | M16: 48 Mpx (ƒ/ 1.6) + 48 Mpx UGA (ƒ/ 2.2) + 48 Mpx Teleobjetivo (ƒ/ 2.8) | N16: SI | O16: 4k | P16: 18 Mpx | Q16: 4823 mAh | R16: 40W | S16: SI, 25W | T16: 6 | U16: SI | V16: FACEID | W16: Hasta Febrero 2033
A17: MOTOROLA G05 128GB | B17: {=IFERROR( _xludf.XLOOKUP("*"&SUBSTITUTE(TRIM(A17)," ","*")&"*", 'RENO CONT'!$C:$C, 'RENO CONT'!$D:$D, "", 2), "")} | C17: {=IFERROR( _xludf.XLOOKUP("*"&SUBSTITUTE(TRIM(A17)," ","*")&"*", 'RENO FINAN'!$A:$A, 'RENO FINAN'!$C:$C, "", 2), "")} | D17: 6.72", HD+, LCD | E17: 189 g | F17: IP54 | G17: 90 Hz | H17: G81 Extreme (12 nm) | I17: 262K | J17: 4 GB (física) + hasta 8 GB (RAM Boost) | K17: 128 GB eMMC 5.1 | L17: Hasta 1Tb | M17: 50 Mpx (ƒ/ 1.8) + Flicker Sensor | N17: NO | O17: 1080p@30fps | P17: 8 Mpx | Q17: 5200 mAh | R17: 18.0W | S17: NO | T17: 5.4 | U17: NO | V17: lateral | W17: Hasta Febrero 2028 | AF17: PLANES MT
A18: Motorola Moto G06 256GB 4G | B18: {=IFERROR( _xludf.XLOOKUP("*"&SUBSTITUTE(TRIM(A18)," ","*")&"*", 'RENO CONT'!$C:$C, 'RENO CONT'!$D:$D, "", 2), "")} | C18: {=IFERROR( _xludf.XLOOKUP("*"&SUBSTITUTE(TRIM(A18)," ","*")&"*", 'RENO FINAN'!$A:$A, 'RENO FINAN'!$C:$C, "", 2), "")} | D18: 6.72", HD+, LCD | E18: 194 g | F18: IP64 | G18: 120 Hz | H18: G81 Extreme (12 nm) | I18: 262K | J18: 4 GB (física) + hasta 8 GB (RAM Boost) | K18: 128 GB eMMC 5.1 | L18: Hasta 1Tb | M18: 50 Mpx (ƒ/ 1.8) + 0.3 Mpx | N18: NO | O18: 1080p@30fps | P18: 8 Mpx | Q18: 5200 mAh | R18: 18.0W | S18: NO | T18: 5.4 | U18: NO | V18: lateral | W18: 7 años
A19: Motorola Moto G15 | B19: {=IFERROR( _xludf.XLOOKUP("*"&SUBSTITUTE(TRIM(A19)," ","*")&"*", 'RENO CONT'!$C:$C, 'RENO CONT'!$D:$D, "", 2), "")} | C19: {=IFERROR( _xludf.XLOOKUP("*"&SUBSTITUTE(TRIM(A19)," ","*")&"*", 'RENO FINAN'!$A:$A, 'RENO FINAN'!$C:$C, "", 2), "")} | D19: 6.72", FHD+, LCD | E19: 190 g | F19: IP54 | G19: 60 Hz | H19: G81 Extreme (12 nm) | I19: 288K | J19: 4 GB (física) + hasta 8 GB (RAM Boost) | K19: 256 GB eMMC 5.1 | L19: - | M19: 50 Mpx (ƒ/ 1.8) + 5 Mpx UGA (ƒ/ 2.4) | N19: NO | O19: 1080p@30fps | P19: 8 Mpx | Q19: 5200 mAh | R19: 20.0W | S19: NO | T19: 5.4 | U19: SI | V19: lateral | W19: 3 años
A20: Motorola Moto G17 256GB 4G | B20: {=IFERROR( _xludf.XLOOKUP("*"&SUBSTITUTE(TRIM(A20)," ","*")&"*", 'RENO CONT'!$C:$C, 'RENO CONT'!$D:$D, "", 2), "")} | C20: {=IFERROR( _xludf.XLOOKUP("*"&SUBSTITUTE(TRIM(A20)," ","*")&"*", 'RENO FINAN'!$A:$A, 'RENO FINAN'!$C:$C, "", 2), "")} | D20: 6.72", FHD+, LCD | E20: 190 g | F20: IP64 | G20: 90 Hz | H20: G81 Extreme (12 nm) | I20: 288K | J20: 4 GB (física) + hasta 8 GB (RAM Boost) | K20: 256 GB eMMC 5.1 | L20: - | M20: 50 Mpx (ƒ/ 1.88) + 5 Mpx UGA (ƒ/ 2.2) | N20: NO | O20: 1080p@30fps | P20: 32 Mpx | Q20: 5200 mAh | R20: 18.0W | S20: NO | T20: 5.4 | U20: NO | V20: lateral | W20: -
A21: MOTOROLA G56 256GB | B21: {=IFERROR( _xludf.XLOOKUP("*"&SUBSTITUTE(TRIM(A21)," ","*")&"*", 'RENO CONT'!$C:$C, 'RENO CONT'!$D:$D, "", 2), "")} | C21: {=IFERROR( _xludf.XLOOKUP("*"&SUBSTITUTE(TRIM(A21)," ","*")&"*", 'RENO FINAN'!$A:$A, 'RENO FINAN'!$C:$C, "", 2), "")} | D21: 6.72", FHD+, LCD | E21: 200 g | F21: IP68, IP69K, MIL-STD-810H | G21: 120 Hz | H21: Dimensity 7060 (6 nm) | I21: 475K | J21: 8 GB (física) | K21: 256 GB UFS 2.1 | L21: Hasta 2Tb | M21: 50 Mpx (ƒ/ 1.88) + 8 Mpx UGA (ƒ/ 2.2) | N21: SI | O21: 1080p@30fps | P21: 32 Mpx | Q21: 5200 mAh | R21: 33.0W | S21: NO | T21: 5.3 | U21: SI | V21: lateral | W21: 4 años
A22: MOTOROLA G77 256GB 5G | B22: {=IFERROR( _xludf.XLOOKUP("*"&SUBSTITUTE(TRIM(A22)," ","*")&"*", 'RENO CONT'!$C:$C, 'RENO CONT'!$D:$D, "", 2), "")} | C22: {=IFERROR( _xludf.XLOOKUP("*"&SUBSTITUTE(TRIM(A22)," ","*")&"*", 'RENO FINAN'!$A:$A, 'RENO FINAN'!$C:$C, "", 2), "")} | D22: 6.78", FHD+, AMOLED | E22: 182 g | F22: IP64 , MIL-STD-810H | G22: 120 Hz | H22: Dimensity 6400 (4 nm) | I22: 449K | J22: 8 GB (física) | K22: 256 GB UFS 2.1 | L22: Hasta 2Tb | M22: 108 Mpx (ƒ/ 1.7) + 8 Mpx UGA (ƒ/ 2.2) | N22: SI | O22: 1080p@30fps | P22: 32 Mpx | Q22: 5200 mAh | R22: 33.0W | S22: NO | T22: 5.4 | U22: SI | V22: Pantalla | W22: 4 años
A23: MOTOROLA EDGE 60 FUSION 256GB 5G | B23: {=IFERROR( _xludf.XLOOKUP("*"&SUBSTITUTE(TRIM(A23)," ","*")&"*", 'RENO CONT'!$C:$C, 'RENO CONT'!$D:$D, "", 2), "")} | C23: {=IFERROR( _xludf.XLOOKUP("*"&SUBSTITUTE(TRIM(A23)," ","*")&"*", 'RENO FINAN'!$A:$A, 'RENO FINAN'!$C:$C, "", 2), "")} | D23: 6.67", QHD+, pOLED | E23: 178 g | F23: IP68, IP69K, MIL-STD-810H | G23: 120 Hz | H23: Dimensity 7300 (4 nm) | I23: 640K | J23: 8 GB (física) + hasta 8 GB (RAM Boost) | K23: 256 GB UFS 2.1 | L23: - | M23: 50 Mpx (ƒ/ 1.88) + 13 Mpx UGA (ƒ/ 2.2) + 5 Mpx Retrato | N23: SI | O23: 4K | P23: 32 Mpx | Q23: 5200 mAh | R23: 68.0W | S23: NO | T23: 5.4 | U23: SI | V23: Pantalla | W23: Hasta el 2029
A24: MOTOROLA EDGE 70 FUSION 256GB 5G | B24: {=IFERROR( _xludf.XLOOKUP("*"&SUBSTITUTE(TRIM(A24)," ","*")&"*", 'RENO CONT'!$C:$C, 'RENO CONT'!$D:$D, "", 2), "")} | C24: {=IFERROR( _xludf.XLOOKUP("*"&SUBSTITUTE(TRIM(A24)," ","*")&"*", 'RENO FINAN'!$A:$A, 'RENO FINAN'!$C:$C, "", 2), "")} | D24: 6.67", QHD+, AMOLED | E24: 177 g | F24: IP68, IP69K, MIL-STD-810H | G24: 144 Hz | H24: Snapdragon 7s Gen 3 (4 nm) | I24: 807k | J24: 8 GB (física) + hasta 16 GB (RAM Boost) | K24: 256 GB UFS 2.2 | L24: NO | M24: 50 Mpx (ƒ/ 1.8) + 13 Mpx UGA (ƒ/ 2.2) | N24: SI | O24: 4K | P24: 32 Mpx | Q24: 5200 mAh | R24: 68.0W | S24: SI | T24: 6 | U24: SI, 15W | V24: Pantalla | W24: Hasta el 2031
A25: OPPO A5 256GB LTE | B25: {=IFERROR( _xludf.XLOOKUP("*"&SUBSTITUTE(TRIM(A25)," ","*")&"*", 'RENO CONT'!$C:$C, 'RENO CONT'!$D:$D, "", 2), "")} | C25: {=IFERROR( _xludf.XLOOKUP("*"&SUBSTITUTE(TRIM(A25)," ","*")&"*", 'RENO FINAN'!$A:$A, 'RENO FINAN'!$C:$C, "", 2), "")} | D25: 6.67", HD+, LCD IPS | E25: 193 g | F25: IP65, MIL-STD-810H | G25: 90 Hz | H25: Snapdragon 6s Gen1 (11 nm) | I25: 405K | J25: 4 GB (física) + hasta 4 GB (RAM Boost) | K25: 256 GB UFS 2.1 | L25: Hasta 1TB | M25: 50 Mpx (ƒ/ 1.8) + 2 Mpx (ƒ/ 2.4) | N25: SI | O25: 1080p@30fps | P25: 5 Mpx | Q25: 6000 mAh | R25: 45.0W | S25: NO | T25: 5 | U25: SI | V25: lateral | W25: 5 años
A26: OPPO A5 256GB 5G | B26: {=IFERROR( _xludf.XLOOKUP("*"&SUBSTITUTE(TRIM(A26)," ","*")&"*", 'RENO CONT'!$C:$C, 'RENO CONT'!$D:$D, "", 2), "")} | C26: {=IFERROR( _xludf.XLOOKUP("*"&SUBSTITUTE(TRIM(A26)," ","*")&"*", 'RENO FINAN'!$A:$A, 'RENO FINAN'!$C:$C, "", 2), "")} | D26: 6.67", HD+, LCD IPS | E26: 194 g | F26: IP65, MIL-STD-810H | G26: 120Hz | H26: Dimensity 6300 (6 nm) | I26: 405K | J26: 8 GB (física) + hasta 8 GB (RAM Boost) | K26: 256 GB UFS 2.2 | L26: Hasta 1TB | M26: 50 Mpx (ƒ/ 1.8) + 2 Mpx (ƒ/ 2.4) | N26: SI | O26: 4K | P26: 8 Mpx | Q26: 6000 mAh | R26: 45.0W | S26: NO | T26: 5.3 | U26: SI | V26: lateral | W26: 5 años
A27: OPPO A5 PRO 256GB | B27: {=IFERROR( _xludf.XLOOKUP("*"&SUBSTITUTE(TRIM(A27)," ","*")&"*", 'RENO CONT'!$C:$C, 'RENO CONT'!$D:$D, "", 2), "")} | C27: {=IFERROR( _xludf.XLOOKUP("*"&SUBSTITUTE(TRIM(A27)," ","*")&"*", 'RENO FINAN'!$A:$A, 'RENO FINAN'!$C:$C, "", 2), "")} | D27: 6.67", HD+, LCD IPS | E27: 194 g | F27: IP68, IP69K, MIL-STD-810H | G27: 120Hz | H27: Dimensity 6300 (6 nm) | I27: 405K | J27: 8 GB (física) + hasta 8 GB (RAM Boost) | K27: 256 GB UFS 2.2 | L27: Hasta 1TB | M27: 50 Mpx (ƒ/ 1.8) + 2 Mpx (ƒ/ 2.4) | N27: SI | O27: 4K | P27: 8 Mpx | Q27: 5800 mAh | R27: 45.0W | S27: NO | T27: 5.3 | U27: SI | V27: lateral | W27: 5 años
A28: OPPO A6X 256GB 5G | B28: {=IFERROR( _xludf.XLOOKUP("*"&SUBSTITUTE(TRIM(A28)," ","*")&"*", 'RENO CONT'!$C:$C, 'RENO CONT'!$D:$D, "", 2), "")} | C28: {=IFERROR( _xludf.XLOOKUP("*"&SUBSTITUTE(TRIM(A28)," ","*")&"*", 'RENO FINAN'!$A:$A, 'RENO FINAN'!$C:$C, "", 2), "")} | D28: 6.75", HD+, PLS | E28: 212 g | F28: IP 64 | G28: 120Hz | H28: Dimensity 6300 (6 nm) | I28: 405K | J28: 4 GB (física) + hasta 4 GB (RAM Boost) | K28: 256 GB UFS 2.2 | L28: Hasta 1TB | M28: 50 Mpx (ƒ/ 1.8) + 2 Mpx (ƒ/ 2.4) | N28: NO | O28: 1080p@30fps | P28: 5 Mpx | Q28: 6100 mAh | R28: 45.0W | S28: NO | T28: 5.4 | U28: SI | V28: lateral | W28: 5 años
A29: OPPO A6 PRO 256GB | B29: {=IFERROR( _xludf.XLOOKUP("*"&SUBSTITUTE(TRIM(A29)," ","*")&"*", 'RENO CONT'!$C:$C, 'RENO CONT'!$D:$D, "", 2), "")} | C29: {=IFERROR( _xludf.XLOOKUP("*"&SUBSTITUTE(TRIM(A29)," ","*")&"*", 'RENO FINAN'!$A:$A, 'RENO FINAN'!$C:$C, "", 2), "")} | D29: 6.57", FHD+, AMOLED | E29: 185 g | F29: IP69, MIL-STD-810H | G29: 120Hz | H29: Dimensity 6300 (6 nm) | I29: 409K | J29: 8 GB (física) + hasta 8 GB (RAM Boost) | K29: 256 GB UFS 2.2 | L29: Hasta 1TB | M29: 50 Mpx (ƒ/ 1.8) + 2 Mpx (ƒ/ 2.4) | N29: SI | O29: 4K | P29: 16 Mpx | Q29: 6500 mAh | R29: 80.0W | S29: NO | T29: 5.4 | U29: SI | V29: lateral | W29: 5 años
A30: OPPO RENO 14F 256GB 5G | B30: {=IFERROR( _xludf.XLOOKUP("*"&SUBSTITUTE(TRIM(A30)," ","*")&"*", 'RENO CONT'!$C:$C, 'RENO CONT'!$D:$D, "", 2), "")} | C30: {=IFERROR( _xludf.XLOOKUP("*"&SUBSTITUTE(TRIM(A30)," ","*")&"*", 'RENO FINAN'!$A:$A, 'RENO FINAN'!$C:$C, "", 2), "")} | D30: 6.57", FHD+, AMOLED | E30: 180 g | F30: IP68, IP69K | G30: 120Hz | H30: Snapdragon 6 Gen1 (4 nm) | I30: 575K | J30: 8 GB (física) + hasta 8 GB (RAM Boost) | K30: 256 GB UFS 3.1 | M30: 50 Mpx (ƒ/ 1.8) + 2 Mpx (ƒ/ 2.4) + 8 Mpx (ƒ/ 2.2) | N30: SI | O30: 4K | P30: 32 Mpx | Q30: 6000 mAh | R30: 45.0W | S30: NO | T30: 5.1 | U30: SI | V30: Pantalla | W30: 6 años
A31: Samsung Galaxy A06 128GB 4G | B31: {=IFERROR( _xludf.XLOOKUP("*"&SUBSTITUTE(TRIM(A31)," ","*")&"*", 'RENO CONT'!$C:$C, 'RENO CONT'!$D:$D, "", 2), "")} | C31: {=IFERROR( _xludf.XLOOKUP("*"&SUBSTITUTE(TRIM(A31)," ","*")&"*", 'RENO FINAN'!$A:$A, 'RENO FINAN'!$C:$C, "", 2), "")} | D31: 6.7", HD+, PLS | E31: 189 g | F31: - | G31: 60 Hz | H31: Helio G85 (12 nm) | I31: 225K | J31: 4 GB (física) + hasta 4 GB (RAM Plus) | K31: 128 GB eMMC 5.1 | L31: Hasta 1TB | M31: 50 Mpx (ƒ/ 1.8) + 2 Mpx (ƒ/ 2.4) | N31: NO | O31: 1080p@60fps | P31: 8 Mpx | Q31: 5000 mAh | R31: 25.0W | S31: NO | T31: 5.3 | U31: NO | V31: lateral | W31: Hasta Agosto 2028
A32: Samsung Galaxy A07 128GB 4G | B32: {=IFERROR( _xludf.XLOOKUP("*"&SUBSTITUTE(TRIM(A32)," ","*")&"*", 'RENO CONT'!$C:$C, 'RENO CONT'!$D:$D, "", 2), "")} | C32: {=IFERROR( _xludf.XLOOKUP("*"&SUBSTITUTE(TRIM(A32)," ","*")&"*", 'RENO FINAN'!$A:$A, 'RENO FINAN'!$C:$C, "", 2), "")} | D32: 6.7", HD+, PLS | E32: 184 g | F32: IP54 | G32: 90 Hz | H32: Helio G99 (6 nm) | I32: 416K | J32: 4 GB (física) + hasta 4 GB (RAM Plus) | K32: 128 GB eMMC 5.1 | L32: Hasta 2Tb | M32: 50 Mpx (ƒ/ 1.8) + 2 Mpx (ƒ/ 2.4) | N32: NO | O32: 1080p@30fps | P32: 8 Mpx | Q32: 5000 mAh | R32: 25.0W | S32: NO | T32: 5.3 | U32: NO | V32: lateral | W32: Hasta Agosto 2031
A33: Samsung Galaxy A17 128GB 5G | B33: {=IFERROR( _xludf.XLOOKUP("*"&SUBSTITUTE(TRIM(A33)," ","*")&"*", 'RENO CONT'!$C:$C, 'RENO CONT'!$D:$D, "", 2), "")} | C33: {=IFERROR( _xludf.XLOOKUP("*"&SUBSTITUTE(TRIM(A33)," ","*")&"*", 'RENO FINAN'!$A:$A, 'RENO FINAN'!$C:$C, "", 2), "")} | D33: 6.7", FHD+, Super AMOLED | E33: 190 g | F33: IP54 | G33: 90 Hz | H33: Exynos 1330 (5 nm) | I33: 419K | J33: 8 GB (física) + hasta 8 GB (RAM Plus) | K33: 128 GB | L33: Hasta 2Tb | M33: 50 Mpx (ƒ/ 1.8) + 5 Mpx UGA (ƒ/ 2.2) + 2 Mpx MACRO (ƒ/ 2.4) | N33: SI | O33: 1080p@30fps | P33: 13 Mpx | Q33: 5000 mAh | R33: 25.0W | S33: NO | T33: 5.3 | U33: NO | V33: lateral | W33: Hasta Septiembre 2031
A34: Samsung Galaxy A16 256GB 4G | B34: {=IFERROR( _xludf.XLOOKUP("*"&SUBSTITUTE(TRIM(A34)," ","*")&"*", 'RENO CONT'!$C:$C, 'RENO CONT'!$D:$D, "", 2), "")} | C34: {=IFERROR( _xludf.XLOOKUP("*"&SUBSTITUTE(TRIM(A34)," ","*")&"*", 'RENO FINAN'!$A:$A, 'RENO FINAN'!$C:$C, "", 2), "")} | D34: 6.7", FHD+, Super AMOLED | E34: 200 g | F34: IP54 | G34: 90 Hz | H34: Helio G99 (6 nm) | I34: 388K | J34: 4 GB (física) + hasta 4 GB (RAM Plus) | K34: 128 GB | L34: Hasta 1.5Tb | M34: 50 Mpx (ƒ/ 1.8) + 5 Mpx UGA (ƒ/ 2.2) + 2 Mpx MACRO (ƒ/ 2.4) | N34: NO | O34: 1080p@30fps | P34: 13 Mpx | Q34: 5000 mAh | R34: 25.0W | S34: NO | T34: 5.3 | U34: SI | V34: lateral | W34: Hasta Noviembre 2030
A35: Samsung Galaxy A26 256GB 5G | B35: {=IFERROR( _xludf.XLOOKUP("*"&SUBSTITUTE(TRIM(A35)," ","*")&"*", 'RENO CONT'!$C:$C, 'RENO CONT'!$D:$D, "", 2), "")} | C35: {=IFERROR( _xludf.XLOOKUP("*"&SUBSTITUTE(TRIM(A35)," ","*")&"*", 'RENO FINAN'!$A:$A, 'RENO FINAN'!$C:$C, "", 2), "")} | D35: 6.7", FHD+, Super AMOLED | E35: 200 g | F35: IP67 | G35: 120 Hz | H35: Exynos 1380 (5 nm) | I35: 574K | J35: 6 GB (física) + hasta 6 GB (RAM Plus) | K35: 128 GB | L35: Hasta 2Tb | M35: 50 Mpx (ƒ/ 1.8) + 5 Mpx UGA (ƒ/ 2.2) + 2 Mpx (ƒ/ 2.4) | N35: SI | O35: 4K | P35: 13 Mpx | Q35: 5000 mAh | R35: 25.0W | S35: NO | T35: 5.3 | U35: SI | V35: lateral | W35: Hasta Marzo 2031
A36: Samsung Galaxy A36 256GB 5G | B36: {=IFERROR( _xludf.XLOOKUP("*"&SUBSTITUTE(TRIM(A36)," ","*")&"*", 'RENO CONT'!$C:$C, 'RENO CONT'!$D:$D, "", 2), "")} | C36: {=IFERROR( _xludf.XLOOKUP("*"&SUBSTITUTE(TRIM(A36)," ","*")&"*", 'RENO FINAN'!$A:$A, 'RENO FINAN'!$C:$C, "", 2), "")} | D36: 6.7", FHD+, Super AMOLED | E36: 195 g | F36: IP67 | G36: 120 Hz | H36: Snapdragon 6 Gen 3 (4 nm) | I36: 550K | J36: 6 GB (física) + hasta 6 GB (RAM Plus) | K36: 128 GB UFS 2.2 | L36: NO | M36: 50 Mpx (ƒ/ 1.8) + 8 Mpx UGA (ƒ/ 2.2) + 8 Mpx MACRO (ƒ/ 2.4) | N36: SI | O36: 4K | P36: 5 Mpx | Q36: 5000 mAh | R36: 45.0W | S36: NO | T36: 5.3 | U36: SI | V36: Pantalla | W36: Hasta Marzo 2031
A37: Samsung Galaxy A37 256GB 5G | B37: {=IFERROR( _xludf.XLOOKUP("*"&SUBSTITUTE(TRIM(A37)," ","*")&"*", 'RENO CONT'!$C:$C, 'RENO CONT'!$D:$D, "", 2), "")} | C37: {=IFERROR( _xludf.XLOOKUP("*"&SUBSTITUTE(TRIM(A37)," ","*")&"*", 'RENO FINAN'!$A:$A, 'RENO FINAN'!$C:$C, "", 2), "")} | D37: 6.7", FHD+, Super AMOLED | E37: 196 g | F37: IP68 | G37: 120 Hz | H37: Exynos 1480 (4 nm) | I37: 731K | J37: 8 GB (física) + hasta 8 GB (RAM Plus) | K37: 256 GB UFS 3.1 | L37: - | M37: 50 Mpx (ƒ/ 1.8) + 8 Mpx UGA (ƒ/ 2.2) + 5 Mpx MACRO (ƒ/ 2.4) | N37: SI | O37: 4K | P37: 12 Mpx | Q37: 5000 mAh | R37: 45.0W | S37: NO | T37: 5.4 | U37: SI | V37: Pantalla | W37: Hasta Marzo 2032
A38: Samsung Galaxy A56 256GB 5G | B38: {=IFERROR( _xludf.XLOOKUP("*"&SUBSTITUTE(TRIM(A38)," ","*")&"*", 'RENO CONT'!$C:$C, 'RENO CONT'!$D:$D, "", 2), "")} | C38: {=IFERROR( _xludf.XLOOKUP("*"&SUBSTITUTE(TRIM(A38)," ","*")&"*", 'RENO FINAN'!$A:$A, 'RENO FINAN'!$C:$C, "", 2), "")} | D38: 6.7", FHD+, Super AMOLED | E38: 197 g | F38: IP67 | G38: 120 Hz | H38: Exynos 1580 (4 nm) | I38: 841K | J38: 8 GB (física) + hasta 8 GB (RAM Plus) | K38: 256 GB UFS 3.1 | L38: NO | M38: 50 Mpx (ƒ/ 1.8) + 13 Mpx UGA (ƒ/ 2.2) + 5 Mpx MACRO (ƒ/ 2.4) | N38: SI | O38: 4K | P38: 12 Mpx | Q38: 5000 mAh | R38: 45.0W | S38: NO | T38: 5.3 | U38: SI | V38: Pantalla | W38: Hasta Marzo 2032
A39: Samsung Galaxy A57 256GB 5G | B39: {=IFERROR( _xludf.XLOOKUP("*"&SUBSTITUTE(TRIM(A39)," ","*")&"*", 'RENO CONT'!$C:$C, 'RENO CONT'!$D:$D, "", 2), "")} | C39: {=IFERROR( _xludf.XLOOKUP("*"&SUBSTITUTE(TRIM(A39)," ","*")&"*", 'RENO FINAN'!$A:$A, 'RENO FINAN'!$C:$C, "", 2), "")} | D39: 6.7", FHD+, Super AMOLED+ | F39: IP68 | G39: 120 Hz | H39: Exynos 1680 (4 nm) | I39: 1120K | J39: 8 GB (física) + hasta 8 GB (RAM Plus) | K39: 256 GB UFS 3.1 | L39: - | M39: 50 Mpx (ƒ/ 1.8) + 8 Mpx UGA (ƒ/ 2.2) + 5 Mpx MACRO (ƒ/ 2.4) | N39: SI | O39: 4K | P39: 12 Mpx | Q39: 5000 mAh | R39: 45.0W | S39: NO | T39: 6 | U39: SI | V39: Pantalla | W39: Hasta Marzo 2032
A40: Samsung Galaxy S26 256GB 5G | B40: {=IFERROR( _xludf.XLOOKUP("*"&SUBSTITUTE(TRIM(A40)," ","*")&"*", 'RENO CONT'!$C:$C, 'RENO CONT'!$D:$D, "", 2), "")} | C40: {=IFERROR( _xludf.XLOOKUP("*"&SUBSTITUTE(TRIM(A40)," ","*")&"*", 'RENO FINAN'!$A:$A, 'RENO FINAN'!$C:$C, "", 2), "")} | D40: 6.3", FHD+, Dynamic AMOLED 2X | E40: 167 g | F40: IP68 | G40: 120 Hz | H40: Exynos 2600 (2 nm) | I40: 2825K | J40: 12 GB (física) + hasta 8 GB (RAM Plus) | K40: 256 GB UFS 4.1 | L40: NO | M40: 50 Mpx (ƒ/ 1.8) + 12 Mpx UGA (ƒ/ 2.2) + 12 Mpx Teleobjetivo (ƒ/ 2.4) | N40: SI | O40: 8K | P40: 12 Mpx | Q40: 4300 mAh | R40: 25.0W | S40: SI, 15W | T40: 5.4 | U40: SI | V40: Pantalla | W40: Hasta Febrero 2033
...

Sheet Imagen
A1: CATALOGO DE EQUIPOS
A2: HONOR 400 | B2: IMAGEN | C2: https://embed.studio.binkies3d.com/live3d/69e129b874c82e003663da95
A3: HONOR 400 LITE | B3: IMAGEN | C3: https://embed.studio.binkies3d.com/live3d/69e129f8a8d031003791f1a7
A4: HONOR MAGIC 7 LITE 512GB | B4: IMAGEN | C4: https://embed.studio.binkies3d.com/live3d/69e12a7bc7300c00376148d6
A5: HONOR MAGIC 8 LITE 512GB 5G | B5: IMAGEN | C5: https://embed.studio.binkies3d.com/live3d/69e12ab0492f94003516cc8a
A6: HONOR X5B | B6: IMAGEN | C6: https://embed.studio.binkies3d.com/live3d/69e12ae6c7300c0037614948
A7: HONOR X5C | B7: IMAGEN | C7: https://embed.studio.binkies3d.com/live3d/69e12b6dc7300c00376149a0
A8: HONOR X6C | B8: IMAGEN | C8: https://embed.studio.binkies3d.com/live3d/69e12b92c7300c00376149f6
A9: HONOR X7C | B9: IMAGEN | C9: https://embed.studio.binkies3d.com/live3d/69e12bf5492f94003516cd5f
A10: HONOR X7D 256GB LTE | B10: IMAGEN | C10: https://embed.studio.binkies3d.com/live3d/69e12c1ca8d031003791f20b
A11: HONOR X8C 256GB | B11: IMAGEN | C11: https://embed.studio.binkies3d.com/live3d/69e12c4bc7300c0037614a81
A12: IPHONE 13 128GB | B12: IMAGEN | C12: https://embed.studio.binkies3d.com/live3d/69e12c8cc7300c0037614adf
A13: IPHONE 15 128GB | B13: IMAGEN | C13: https://embed.studio.binkies3d.com/live3d/69e12ccac7300c0037614b7e
... A74: Honor 600 512GB 5G | B74: IMAGEN | C74: https://embed.studio.binkies3d.com/live3d/6a6e70f8c6517e003644ef79

Sheet RENO CONT
A1: GAMA | B1: TÁCTICA | C1: MODELO | D1: 29.9 29.9R 31.40B 32.9 34.9 35.9 39.9 42.9 44.9 45.9 49.9 | E1: 53.9 54.9 59.9 63.9 | F1: 69.9 74.9 79.9 | G1: 89.9 94.9 99.9 | H1: 104.9 115.9 129.9 | I1: 159.9 | J1: 199.9 | K1: PLAN BLACK
A2: Mid | B2: - | C2: Xiaomi Redmi 9 | D2: =VLOOKUP(C2,'[1]RENO CONTADO SIN FIN'!C:J,2,0)*0.9 -> #N/A | E2: =VLOOKUP(C2,'[1]RENO CONTADO SIN FIN'!C:J,3,0)*0.9 -> #N/A | F2: =VLOOKUP(C2,'[1]RENO CONTADO SIN FIN'!C:K,4,0)*0.9 -> #N/A | G2: =VLOOKUP(C2,'[1]RENO CONTADO SIN FIN'!C:J,5,0)*0.9 -> #N/A | H2: =VLOOKUP(C2,'[1]RENO CONTADO SIN FIN'!C:J,6,0)*0.9 -> #N/A | I2: =VLOOKUP(C2,'[1]RENO CONTADO SIN FIN'!C:J,7,0)*0.9 -> #N/A | J2: =VLOOKUP(C2,'[1]RENO CONTADO SIN FIN'!C:J,8,0)*0.9 -> #N/A | K2: =VLOOKUP(C2,'[1]RENO CONTADO SIN FIN'!C:K,9,0)*0.9 -> #N/A
A3: Entry Smart | B3: - | C3: Xiaomi Redmi 9A | D3: 179.1 | E3: 179.1 | F3: 179.1 | G3: 179.1 | H3: 179.1 | I3: 179.1 | J3: 179.1 | K3: 179.1
A4: Entry Smart | B4: - | C4: Xiaomi Redmi A1 32GB | D4: 209.7 | E4: 209.7 | F4: 209.7 | G4: 209.7 | H4: 209.7 | I4: 209.7 | J4: 209.7 | K4: 209.7
A5: Entry Smart | B5: - | C5: Samsung Galaxy A04e 32GB | D5: 259.2 | E5: 259.2 | F5: 259.2 | G5: 259.2 | H5: 259.2 | I5: 259.2 | J5: 259.2 | K5: 259.2
A6: Entry Smart | B6: - | C6: ZTE Blade A5 2020 32GB | D6: 339.3 | E6: 339.3 | F6: 339.3 | G6: 339.3 | H6: 339.3 | I6: 339.3 | J6: 339.3 | K6: 339.3
A7: High | B7: - | C7: Samsung Galaxy A52 | D7: 749.7 | E7: 749.7 | F7: 749.7 | G7: 749.7 | H7: 749.7 | I7: 749.7 | J7: 749.7 | K7: 749.7
A8: Entry Smart | B8: - | C8: Motorola Moto E7i Power | D8: 189 | E8: 189 | F8: 189 | G8: 189 | H8: 189 | I8: 189 | J8: 189 | K8: 189
A9: Mid | B9: - | C9: Xiaomi Redmi Note 10 | D9: 829.8 | E9: 829.8 | F9: 829.8 | G9: 829.8 | H9: 829.8 | I9: 829.8 | J9: 829.8 | K9: 829.8
A10: Mid | B10: - | C10: Xiaomi Redmi Note 10 5G | D10: 409.5 | E10: 409.5 | F10: 409.5 | G10: 409.5 | H10: 409.5 | I10: 409.5 | J10: 409.5 | K10: 409.5
A11: High | B11: - | C11: Xiaomi Redmi Note 10 Pro | D11: 899.1 | E11: 899.1 | F11: 899.1 | G11: 899.1 | H11: 899.1 | I11: 899.1 | J11: 899.1 | K11: 899.1
A12: Premium | B12: - | C12: Samsung Galaxy S20 FE | D12: 1179 | E12: 1179 | F12: 1179 | G12: 1179 | H12: 1179 | I12: 1179 | J12: 1179 | K12: 1179
A13: Premium | B13: - | C13: Samsung Galaxy S21 FE 5G | D13: 1499.4 | E13: 1499.4 | F13: 1499.4 | G13: 1499.4 | H13: 1499.4 | I13: 1499.4 | J13: 1499.4 | K13: 1499.4
A14: Mid | B14: - | C14: Motorola Moto G20 | D14: 249.3 | E14: 249.3 | F14: 249.3 | G14: 249.3 | H14: 249.3 | I14: 249.3 | J14: 249.3 | K14: 249.3
... A425: PremiumPlus | B425: - | C425: Honor 600 Smart 256GB 5G | D425: 1389.6 | E425: 1389.6 | F425: 1389.6 | G425: 1389.6 | H425: 1389.6 | I425: 1389.6 | J425: 1389.6 | K425: 1389.6

Sheet RENO FINAN
A1: 1 | D1: 19
A2: Modelo | B2: Cuota Inicial | C2: Cuota 1 | D2: Cuota 2 a la 12 | E2: Numero de cuotas | F2: Monto Total | G2: La cuota inicial definitiva se determinará al momento de realizar la evaluación comercial en OT
A3: Xiaomi Redmi 9 | B3: 0 | C3: 50 | D3: 48 | E3: 12 | F3: 578
A4: Xiaomi Redmi 9A | B4: 0 | C4: 26 | D4: 28 | E4: 12 | F4: 334
A5: Xiaomi Redmi A1 32GB | B5: 0 | C5: 28 | D5: 33 | E5: 12 | F5: 391
A6: Samsung Galaxy A04e 32GB | B6: 0 | C6: 44 | D6: 40 | E6: 12 | F6: 484
A7: ZTE Blade A5 2020 32GB | B7: 0 | C7: 50 | D7: 53 | E7: 12 | F7: 633
A8: Samsung Galaxy A52 | B8: 0 | C8: 112 | D8: 117 | E8: 12 | F8: 1399
A9: Motorola Moto E7i Power | B9: 0 | C9: 34 | D9: 29 | E9: 12 | F9: 353
A10: Xiaomi Redmi Note 10 | B10: 0 | C10: 130 | D10: 129 | E10: 12 | F10: 1549
A11: Xiaomi Redmi Note 10 5G | B11: 0 | C11: 60 | D11: 64 | E11: 12 | F11: 764
A12: Xiaomi Redmi Note 10 Pro | B12: 0 | C12: 138 | D12: 140 | E12: 12 | F12: 1678
A13: Samsung Galaxy S20 FE | B13: 0 | C13: 188 | D13: 183 | E13: 12 | F13: 2201
A14: Samsung Galaxy S21 FE 5G | B14: 0 | C14: 236 | D14: 233 | E14: 12 | F14: 2799
... A423: Samsung Galaxy S23 256GB SN | B423: 0 | C423: 260 | D423: 263 | E423: 12 | F423: 3153

Sheet PORT CONT
D1: PLANES
A2: GAMA | B2: TÁCTICA | C2: MODELO | D2: 29.9 34.9 39.9 44.9 49.9 | E2: 53.9 54.9 59.9 | F2: 63.9 69.9 74.9 79.9 | G2: 89.9 94.9 99.9 | H2: 104.9 | I2: 129.9 | J2: 199.9 | K2: PLAN BLACK
A3: Mid | B3: - | C3: Xiaomi Redmi 9 | D3: 309.6 | E3: 309.6 | F3: 309.6 | G3: 309.6 | H3: 309.6 | I3: 309.6 | J3: 309.6 | K3: 309.6
A4: Entry Smart | B4: - | C4: Xiaomi Redmi 9A | D4: 179.1 | E4: 179.1 | F4: 179.1 | G4: 179.1 | H4: 179.1 | I4: 179.1 | J4: 179.1 | K4: 179.1
A5: Entry Smart | B5: - | C5: Xiaomi Redmi A1 32GB | D5: 209.7 | E5: 209.7 | F5: 209.7 | G5: 209.7 | H5: 209.7 | I5: 209.7 | J5: 209.7 | K5: 209.7
A6: Entry Smart | B6: - | C6: Samsung Galaxy A04e 32GB | D6: 259.2 | E6: 259.2 | F6: 259.2 | G6: 259.2 | H6: 259.2 | I6: 259.2 | J6: 259.2 | K6: 259.2
A7: Entry Smart | B7: - | C7: ZTE Blade A5 2020 32GB | D7: 339.3 | E7: 339.3 | F7: 339.3 | G7: 339.3 | H7: 339.3 | I7: 339.3 | J7: 339.3 | K7: 339.3
A8: High | B8: - | C8: Samsung Galaxy A52 | D8: 749.7 | E8: 749.7 | F8: 749.7 | G8: 749.7 | H8: 749.7 | I8: 749.7 | J8: 749.7 | K8: 749.7
A9: Entry Smart | B9: - | C9: Motorola Moto E7i Power | D9: 189 | E9: 189 | F9: 189 | G9: 189 | H9: 189 | I9: 189 | J9: 189 | K9: 189
A10: Mid | B10: - | C10: Xiaomi Redmi Note 10 | D10: 829.8 | E10: 829.8 | F10: 829.8 | G10: 829.8 | H10: 829.8 | I10: 829.8 | J10: 829.8 | K10: 829.8
A11: Mid | B11: - | C11: Xiaomi Redmi Note 10 5G | D11: 409.5 | E11: 409.5 | F11: 409.5 | G11: 409.5 | H11: 409.5 | I11: 409.5 | J11: 409.5 | K11: 409.5
A12: High | B12: - | C12: Xiaomi Redmi Note 10 Pro | D12: 899.1 | E12: 899.1 | F12: 899.1 | G12: 899.1 | H12: 899.1 | I12: 899.1 | J12: 899.1 | K12: 899.1
A13: Premium | B13: - | C13: Samsung Galaxy S20 FE | D13: 1179 | E13: 1179 | F13: 1179 | G13: 1179 | H13: 1179 | I13: 1179 | J13: 1179 | K13: 1179
A14: Premium | B14: - | C14: Samsung Galaxy S21 FE 5G | D14: 1499.4 | E14: 1499.4 | F14: 1499.4 | G14: 1499.4 | H14: 1499.4 | I14: 1499.4 | J14: 1499.4 | K14: 1499.4
... A423: PremiumPlus | B423: Seminuevos | C423: Samsung Galaxy S23 256GB SN | D423: 1689.3 | E423: 1689.3 | F423: 1689.3 | G423: 1689.3 | H423: 1689.3 | I423: 1689.3 | J423: 1689.3 | K423: 1689.3

Sheet PORTA FINAN
A1: 1 | D1: 19
A2: Modelo | B2: Cuota Inicial | C2: Cuota 1 | D2: Cuota 2 a la 12 | E2: Numero de cuotas | F2: Monto Total | G2: La cuota inicial definitiva se determinará al momento de realizar la evaluación comercial en OT
A3: Xiaomi Redmi 9 | B3: 0 | C3: 50 | D3: 48 | E3: 12 | F3: 578
A4: Xiaomi Redmi 9A | B4: 0 | C4: 26 | D4: 28 | E4: 12 | F4: 334
A5: Xiaomi Redmi A1 32GB | B5: 0 | C5: 28 | D5: 33 | E5: 12 | F5: 391
A6: Samsung Galaxy A04e 32GB | B6: 0 | C6: 44 | D6: 40 | E6: 12 | F6: 484
A7: ZTE Blade A5 2020 32GB | B7: 0 | C7: 50 | D7: 53 | E7: 12 | F7: 633
A8: Samsung Galaxy A52 | B8: 0 | C8: 112 | D8: 117 | E8: 12 | F8: 1399
A9: Motorola Moto E7i Power | B9: 0 | C9: 34 | D9: 29 | E9: 12 | F9: 353
A10: Xiaomi Redmi Note 10 | B10: 0 | C10: 130 | D10: 129 | E10: 12 | F10: 1549
A11: Xiaomi Redmi Note 10 5G | B11: 0 | C11: 60 | D11: 64 | E11: 12 | F11: 764
A12: Xiaomi Redmi Note 10 Pro | B12: 0 | C12: 138 | D12: 140 | E12: 12 | F12: 1678
A13: Samsung Galaxy S20 FE | B13: 0 | C13: 188 | D13: 183 | E13: 12 | F13: 2201
A14: Samsung Galaxy S21 FE 5G | B14: 0 | C14: 236 | D14: 233 | E14: 12 | F14: 2799
... A423: Samsung Galaxy S23 256GB SN | B423: 0 | C423: 260 | D423: 263 | E423: 12 | F423: 3153

Sheet VR CONT
D1: PLANES
A2: GAMA | B2: TÁCTICA | C2: MODELO | D2: 29.9 34.9 39.9 44.9 49.9 | E2: 53.9 54.9 59.9 | F2: 63.9 69.9 74.9 79.9 | G2: 89.9 94.9 99.9 | H2: 104.9 | I2: 129.9 | J2: 199.9 | K2: PLAN BLACK
A3: Mid | B3: - | C3: Xiaomi Redmi 9 | D3: 309.6 | E3: 309.6 | F3: 309.6 | G3: 309.6 | H3: 309.6 | I3: 309.6 | J3: 309.6 | K3: 309.6
A4: Entry Smart | B4: - | C4: Xiaomi Redmi 9A | D4: 179.1 | E4: 179.1 | F4: 179.1 | G4: 179.1 | H4: 179.1 | I4: 179.1 | J4: 179.1 | K4: 179.1
A5: Entry Smart | B5: - | C5: Xiaomi Redmi A1 32GB | D5: 209.7 | E5: 209.7 | F5: 209.7 | G5: 209.7 | H5: 209.7 | I5: 209.7 | J5: 209.7 | K5: 209.7
A6: Entry Smart | B6: - | C6: Samsung Galaxy A04e 32GB | D6: 259.2 | E6: 259.2 | F6: 259.2 | G6: 259.2 | H6: 259.2 | I6: 259.2 | J6: 259.2 | K6: 259.2
A7: Entry Smart | B7: - | C7: ZTE Blade A5 2020 32GB | D7: 339.3 | E7: 339.3 | F7: 339.3 | G7: 339.3 | H7: 339.3 | I7: 339.3 | J7: 339.3 | K7: 339.3
A8: High | B8: - | C8: Samsung Galaxy A52 | D8: 749.7 | E8: 749.7 | F8: 749.7 | G8: 749.7 | H8: 749.7 | I8: 749.7 | J8: 749.7 | K8: 749.7
A9: Entry Smart | B9: - | C9: Motorola Moto E7i Power | D9: 189 | E9: 189 | F9: 189 | G9: 189 | H9: 189 | I9: 189 | J9: 189 | K9: 189
A10: Mid | B10: - | C10: Xiaomi Redmi Note 10 | D10: 829.8 | E10: 829.8 | F10: 829.8 | G10: 829.8 | H10: 829.8 | I10: 829.8 | J10: 829.8 | K10: 829.8
A11: Mid | B11: - | C11: Xiaomi Redmi Note 10 5G | D11: 409.5 | E11: 409.5 | F11: 409.5 | G11: 409.5 | H11: 409.5 | I11: 409.5 | J11: 409.5 | K11: 409.5
A12: High | B12: - | C12: Xiaomi Redmi Note 10 Pro | D12: 899.1 | E12: 899.1 | F12: 899.1 | G12: 899.1 | H12: 899.1 | I12: 899.1 | J12: 899.1 | K12: 899.1
A13: Premium | B13: - | C13: Samsung Galaxy S20 FE | D13: 1179 | E13: 1179 | F13: 1179 | G13: 1179 | H13: 1179 | I13: 1179 | J13: 1179 | K13: 1179
A14: Premium | B14: - | C14: Samsung Galaxy S21 FE 5G | D14: 1499.4 | E14: 1499.4 | F14: 1499.4 | G14: 1499.4 | H14: 1499.4 | I14: 1499.4 | J14: 1499.4 | K14: 1499.4
... A423: PremiumPlus | B423: Seminuevos | C423: Samsung Galaxy S23 256GB SN | D423: 1689.3 | E423: 1689.3 | F423: 1689.3 | G423: 1689.3 | H423: 1689.3 | I423: 1689.3 | J423: 1689.3 | K423: 1689.3

Sheet VR FINAN
A1: 1 | D1: 19
A2: Modelo | B2: Cuota Inicial | C2: Cuota 1 | D2: Cuota 2 a la 12 | E2: Numero de cuotas | F2: Monto Total | G2: La cuota inicial definitiva se determinará al momento de realizar la evaluación comercial en OT
A3: Xiaomi Redmi 9 | B3: 0 | C3: 50 | D3: 48 | E3: 12 | F3: 578
A4: Xiaomi Redmi 9A | B4: 0 | C4: 26 | D4: 28 | E4: 12 | F4: 334
A5: Xiaomi Redmi A1 32GB | B5: 0 | C5: 28 | D5: 33 | E5: 12 | F5: 391
A6: Samsung Galaxy A04e 32GB | B6: 0 | C6: 44 | D6: 40 | E6: 12 | F6: 484
A7: ZTE Blade A5 2020 32GB | B7: 0 | C7: 50 | D7: 53 | E7: 12 | F7: 633
A8: Samsung Galaxy A52 | B8: 0 | C8: 112 | D8: 117 | E8: 12 | F8: 1399
A9: Motorola Moto E7i Power | B9: 0 | C9: 34 | D9: 29 | E9: 12 | F9: 353
A10: Xiaomi Redmi Note 10 | B10: 0 | C10: 130 | D10: 129 | E10: 12 | F10: 1549
A11: Xiaomi Redmi Note 10 5G | B11: 0 | C11: 60 | D11: 64 | E11: 12 | F11: 764
A12: Xiaomi Redmi Note 10 Pro | B12: 0 | C12: 138 | D12: 140 | E12: 12 | F12: 1678
A13: Samsung Galaxy S20 FE | B13: 0 | C13: 188 | D13: 183 | E13: 12 | F13: 2201
A14: Samsung Galaxy S21 FE 5G | B14: 0 | C14: 236 | D14: 233 | E14: 12 | F14: 2799
... A423: Samsung Galaxy S23 256GB SN | B423: 0 | C423: 260 | D423: 263 | E423: 12 | F423: 3153

Sheet Imagen (2)
A1: CATALOGO DE EQUIPOS
A2: HONOR MAGIC 7 LITE 512GB | B2: IMAGEN PARTE DELANTERA | C2: https://i.ebayimg.com/images/g/vOkAAOSwgkBnhgYQ/s-l1600.webp | D2: IMAGEN PARTE TRASERA | E2: https://i.ebayimg.com/images/g/87cAAOSwD1NnhgYT/s-l1600.webp
A3: HONOR X5B 128GB | B3: IMAGEN PARTE DELANTERA | C3: https://covercompany.com.uy/cdn/shop/files/2-5934_14201_4.jpg?v=1732820170 | D3: IMAGEN PARTE TRASERA | E3: https://covercompany.com.uy/cdn/shop/files/2-5934_14201_3.jpg?v=1732819982
A4: HONOR X6C 256GB | B4: IMAGEN PARTE DELANTERA | C4: https://www.peru-smart.com/wp-content/uploads/2025/07/CELU1107AZUL-256GB_1.jpg | D4: IMAGEN PARTE TRASERA | E4: https://www.peru-smart.com/wp-content/uploads/2025/07/CELU1107AZUL-256GB_0.jpg
A5: HONOR X7C 256GB | B5: IMAGEN PARTE DELANTERA | C5: https://webstoreshops.com/cdn/shop/files/HONOR_X7C_White-3.jpg?v=1737559775&width=800 | D5: IMAGEN PARTE TRASERA | E5: https://webstoreshops.com/cdn/shop/files/HONOR_X7C_White-2.jpg?v=1737559961&width=800
A6: HONOR X8C 256GB | B6: IMAGEN PARTE DELANTERA | C6: https://rimage.ripley.com.pe/home.ripley/Attachment/MKP/3539/PMP20000745981/full_image-1.jpeg | D6: IMAGEN PARTE TRASERA | E6: https://soytechno.com/wp-content/uploads/2025/05/HONOR-X8C-ABR-LX3-CLOUD-PURPLE-3.jpg
A7: IPHONE 13 128GB | B7: IMAGEN PARTE DELANTERA | C7: https://inverfin.com.py/cdn/shop/files/99991627492109_TEL.IPH.13.128.BLA_1.jpg?v=1725987794&width=823 | D7: IMAGEN PARTE TRASERA | E7: https://me-tiendamexpress.s3.us-east-1.amazonaws.com/images/thumbs/0059161_celular-apple-iphone-13-128gb-blanco_600.jpeg
A8: MOTOROLA G05 128GB | B8: IMAGEN PARTE DELANTERA | C8: https://m.media-amazon.com/images/I/71OVsSh822L._AC_SX569_.jpg | D8: IMAGEN PARTE TRASERA | E8: https://m.media-amazon.com/images/I/81RrrX8vpIL._AC_SX569_.jpg
A9: MOTOROLA G15 256GB | B9: IMAGEN PARTE DELANTERA | C9: https://m.media-amazon.com/images/I/51daXYKSyOL._AC_SX679_.jpg | D9: IMAGEN PARTE TRASERA | E9: https://m.media-amazon.com/images/I/619G60+TY-L._AC_SX679_.jpg
A10: MOTOROLA G56 256GB | B10: IMAGEN PARTE DELANTERA | C10: https://bsimg.nl/images/motorola-moto-g56-5g-8gb-256gb-groen_1.png/n-s3tDVQ3aeoNxKSrJEA0et3_G8%3D/fit-in/771x1200/filters%3Aformat%28webp%29%3Aupscale%28%29 | D10: IMAGEN PARTE TRASERA | E10: https://bsimg.nl/images/motorola-moto-g56-5g-8gb-256gb-groen_2.png/kGRkER2wCFObuCEv4y-YAoPdVnc%3D/fit-in/771x1200/filters%3Aformat%28webp%29%3Aupscale%28%29
A11: MOTOROLA EDGE 60 FUSION 256GB 5G | B11: IMAGEN PARTE DELANTERA | C11: https://cdn-files.kimovil.com/phone_front/0011/67/thumb_1066808_phone_front_big.jpg | D11: IMAGEN PARTE TRASERA | E11: https://cdn-files.kimovil.com/default/0011/67/thumb_1066804_default_big.jpg
A12: OPPO A5 256GB 5G | B12: IMAGEN PARTE DELANTERA | C12: https://www.maxmovil.com/media/catalog/product/cache/2c055c968235f5bf43b443aee4bb62c6/o/p/oppo_a5_5g_verde_2_.png | D12: IMAGEN PARTE TRASERA | E12: https://www.ispotaba.com/wp-content/uploads/2025/07/Oppo-A5-Mist-White-Back.jpg
A13: OPPO A5 PRO 256GB | B13: IMAGEN PARTE DELANTERA | C13: https://www.maxmovil.com/media/catalog/product/cache/2c055c968235f5bf43b443aee4bb62c6/o/p/oppo_a5_pro_5g_verde_1_.png | D13: IMAGEN PARTE TRASERA | E13: https://www.maxmovil.com/media/catalog/product/cache/2c055c968235f5bf43b443aee4bb62c6/o/p/oppo_a5_pro_5g_verde_4_.png
... A58: ZTE NUBIA V80 MAX 256GB LTE | B58: IMAGEN PARTE DELANTERA | C58: https://claroperupoc.vtexassets.com/arquivos/ids/2956850/ZTE-NUBIA-V80-MAX-256GB-NEGRO-04.jpg?v=639105733666730000 | D58: IMAGEN PARTE TRASERA | E58: https://claroperupoc.vtexassets.com/arquivos/ids/2956848/ZTE-NUBIA-V80-MAX-256GB-NEGRO-02.jpg?v=639105733666430000

Sheet Precio
A1: En precio, quiero que vaya dos segmentos: Contado y cuota x 12 meses. Tambien cuando el mouse pase por la imagen diga algo como "haz click para voltear la imagen".
A2: EQUIPO | B2: PRECIO AL CONTADO | C2: FINANCIADO | D2: CUOTA X 12 MESES
A3: HONOR MAGIC 7 LITE 512GB | B3: 1399 | C3: 2448 | D3: =C3/12 -> 204
A4: HONOR X5B 128GB | B4: 399 | C4: 732 | D4: =C4/12 -> 61
A5: HONOR X6C 256GB | B5: 579 | C5: 1080 | D5: =C5/12 -> 90
A6: HONOR X7C 256GB | B6: 749 | C6: 1404 | D6: =C6/12 -> 117
A7: HONOR X8C 256GB | B7: 899 | C7: 1644 | D7: =C7/12 -> 137
A8: IPHONE 13 128GB | B8: 2009 | C8: 3516 | D8: =C8/12 -> 293
A9: MOTOROLA G05 128GB | B9: 349 | C9: 648 | D9: =C9/12 -> 54
A10: MOTOROLA G15 256GB | B10: 469 | C10: 876 | D10: =C10/12 -> 73
A11: MOTOROLA G56 256GB | B11: 849 | C11: 1584 | D11: =C11/12 -> 132
A12: OPPO A5 5G 256GB | B12: 999 | C12: 1824 | D12: =C12/12 -> 152
A13: OPPO A5 PRO 256GB | B13: 1299 | C13: 2268 | D13: =C13/12 -> 189
A14: OPPO A5 4G 256GB | B14: 699 | C14: 1284 | D14: =C14/12 -> 107
... A27: ZTE BLADE V70 MAX 256GB | B27: 449 | C27: 840 | D27: =C27/12 -> 70

Sheet Hoja3
A1: 📱 Pantalla | B1: 6.78" AMOLED | C1: 6.56" IPS LCD | D1: 6.56" IPS LCD
A2: 💧 Resistencia al Agua | B2: IP64 | C2: No | D2: No
A3: 🔄 Tasa de Refresco | B3: 120Hz | C3: 90Hz | D3: 90Hz
A4: ⚡ Procesador | B4: Snapdragon 6 Gen 1 | C4: Unisoc Tiger T606 | D4: Unisoc Tiger T606
A5: 🧠 RAM | B5: 8GB | C5: 4GB | D5: 4GB
A6: 💾 Almacenamiento | B6: 512GB | C6: 128GB | D6: 256GB
A7: 📷 Cámaras Traseras | B7: 3 cámaras traseras | C7: 1 cámara trasera | D7: 2 cámaras traseras
A8: 📸 Cámara Principal | B8: 108MP Principal | C8: 50MP Principal | D8: 50MP Principal
A9: 📐 Cámara Ultra Gran Angular | B9: 5MP Ultra Gran Angular | C9: No | D9: 2MP Profundidad
A10: 🔭 Cámara Teleobjetivo | B10: 2MP Macro | C10: No | D10: No
A11: 🔍 Cámara Macro | B11: Sí | C11: No | D11: No
A12: 📹 Estabilización Óptica | B12: No | C12: No | D12: No
... A20: ⚖️ Peso | B20: 189g | C20: 192g | D20: 194g

Sheet link
A1: LAS ESPECIFICACIONES COMO EL PROCESADOR, BATERIA, RESISTENCIA, PANTALLA, ETC. REVISA DESDE EL FONDO. IPHONE 13 https://www.kimovil.com/es/donde-comprar-apple-iphone-13 HONOR X5B https://www.kimovil.com/es/donde-comprar-honor-x5b HONOR X6C https://www.kimovil.com/es/donde-comprar-honor-x6b HONOR X7C https://www.honor.com/mx/phones/honor-7c/spec/ HONOR X8C https://www.kimovil.com/es/donde-comprar-honor-x8c MOTO G05 https://www.kimovil.com/es/donde-comprar-motorola-moto-g05 MOTO G15 https://www.kimovil.com/es/donde-comprar-motorola-moto-g15 MOTO G56 https://www.kimovil.com/es/donde-comprar-motorola-moto-g56-5g OPPO A5 PRO https://www.kimovil.com/es/donde-comprar-oppo-a5-pro-5g RENO 14F https://www.kimovil.com/es/donde-comprar-oppo-reno14-f SAMSUNG A06 https://www.kimovil.com/es/donde-comprar-samsung-galaxy-a06 SAMSUNG A16 https://www.kimovil.com/es/donde-comprar-samsung-galaxy-a16-4g SAMSUNG A26 https://www.kimovil.com/es/donde-comprar-samsung-galaxy-a26-5g SAMSUNG A36 https://www.kimovil.com/es/donde-comprar-samsung-galaxy-a36 SAMSUNG A56 https://www.kimovil.com/es/donde-comprar-samsung-galaxy-a56 XIAOMI REDMI NOTE 14 https://www.kimovil.com/es/donde-comprar-xiaomi-redmi-note-14 XIAOMI REDMI NOTE 14 PRO 4G https://www.kimovil.com/es/donde-comprar-xiaomi-redmi-note-14-pro-4g ZTE BLADE A35 https://www.kimovil.com/es/donde-comprar-zte-blade-a35 ZTE BLADE A55 https://www.kimovil.com/es/donde-comprar-zte-blade-a55 ZTE BLADE A56 PRO https://miportal.entel.pe/personas/producto/equipos/zte-blade-a56-pro/prod940041 ZTE BLADE V70 https://www.ztedevices.com/en/products/smartphones/blade/zte-blade-v70.html ZTE BLADE V70 VITA https://www.kimovil.com/es/donde-comprar-zte-blade-v70-vita
